Workbook

Sheet C-Summary
A1: RSU 5 Financial Analysis: Executive Summary
A3: All values are live formulas. To test scenarios, change yellow cells on I- and C-FY28Projection sheets.
A5: PART 1: FY27 (2026-2027) -- Budget Going to Voters
B6: Amount | C6: % of FY26
A7: FY26 Adopted Budget | B7: ='I-Budget'!B32
A8: FY27 Proposed (Superintendent) | B8: ='C-Budget'!B16 | C8: ='C-Budget'!B18
A9: Dollar increase from FY26 | B9: ='C-Budget'!B17
A10: Superintendent's initial request was 10.55% | B10: ='I-FY27Reductions'!B17
A11: Total staff/program reductions already applied | B11: ='C-FY27Scenarios'!B16
A12: of which: T1 teaching positions | B12: ='C-FY27Scenarios'!B13
A13: of which: T2 support positions | B13: ='C-FY27Scenarios'!B14
A14: Board adopts March 25, 2026 | ABM: May 13 | Referendum: June 19
A15: EC mandate and structural changes are NOT in FY27. They are FY28.
A16: Historical: FY26 approved at 6.83% (817-494); FY25 at 6.48%; FY24 at 4.99%.
A18: PART 2: FY28 (2027-2028) -- Baseline (No Structural Action)
A19: FY27 adopted (selected scenario) | B19: ='C-FY28Projection'!B7
A20: + Annual cost growth | B20: ='C-FY28Projection'!B7*'C-FY28Projection'!B15
A21: + EC mandate net cost (midpoint) | B21: ='C-FY28Projection'!B19
A22: FY28 BASELINE (no restructuring) | B22: ='C-FY28Projection'!B23
A23: FY28 baseline increase from FY27 | B23: ='C-FY28Projection'!B24
A25: PART 3: PATH A -- Preserve & Strengthen (FY28)
A26: Consolidate middle grades for efficiency. Preserve all elementary schools. Distribute EC.
A27: Structural Change | B27: Annual Budget Impact | C27: Source Sheet
A28: 1. Consolidate grades 7-8 at FMS (district-wide) | B28: =-'C-MSConsol'!B19 | C28: C-MSConsol: Teacher savings from 7-8 consolidation
A29: 2. Consolidate grade 6 at DCS (district-wide) | B29: =0 | C29: C-MSConsol: Included in net FTE calc above
A30: 3. Extracurricular consolidation savings | B30: =-'C-MSConsol'!B20 | C30: C-MSConsol: Combined athletics/activities
A31: 4. Freeport 6th-grade transportation to DCS | B31: ='I-Assumptions'!B13*'I-Assumptions'!B12 | C31: I-Assumptions: 2 routes x $75K
A32: 5. DCS portable classrooms needed | B32: =0 | C32: Net zero: gains 6th sections, loses 7-8 sections
A33: 6. DCS admin complexity (multi-community 6th) | B33: =0 | C33: Complexity offsets any admin savings
A34: 7. Additional line-item efficiencies (midpoint) | B34: =-AVERAGE('I-Assumptions'!B22,'I-Assumptions'!B23) | C34: I-Assumptions: transport, facilities, attrition
A35: TOTAL PATH A SAVINGS (cross-check) | B35: =-SUM(B28:B34)
A36: Path A: FY28 adjusted budget | B36: =B22+SUM(B28:B34)
A37: Path A: FY28 increase from FY27 | B37: =(B36-'C-FY28Projection'!B7)/'C-FY28Projection'!B7
A38: What does NOT change: PES stays PreK-5. All 3 elementary schools preserved.
A39: EC distributed: SpEd classroom at MSS (64 PreK peers for LRE). Itinerant EC at all schools.
A40: Net FTE reduction: ~2.4 teachers (from MS consolidation only).
A42: PART 4: PATH B -- Scenario 2 / Full Restructuring (FY28)
A43: Close PES as K-5. Pownal K-6 to DCS. All PreK to PES (EC center). District-wide 7-8 at FMS.
A44: Component | B44: Gross Lens | C44: True Efficiency
A45: PES instruction budget eliminated | B45: ='C-FY28Paths'!B18 | C45: --
...

Sheet C-DOEStaffing
A1: CALC: DOE Staffing Trend Analysis
A3: All values are formulas referencing I-DOEStaffing. Source: Maine DOE [Fn 45]
A5: 1. Ten-Year Total FTE Change by School (2016 to 2026)
A6: School | B6: 2016 FTE | C6: 2026 FTE | D6: Change | E6: % Change
A7: PES (Pownal Elementary) | B7: ='I-DOEStaffing'!B11 | C7: ='I-DOEStaffing'!L11 | D7: =C7-B7 | E7: =D7/B7
A8: DCS (Durham Community) | B8: ='I-DOEStaffing'!B12 | C8: ='I-DOEStaffing'!L12 | D8: =C8-B8 | E8: =D8/B8
A9: MSS (Morse Street) | B9: ='I-DOEStaffing'!B13 | C9: ='I-DOEStaffing'!L13 | D9: =C9-B9 | E9: =D9/B9
A10: MLS (Mast Landing) | B10: ='I-DOEStaffing'!B14 | C10: ='I-DOEStaffing'!L14 | D10: =C10-B10 | E10: =D10/B10
A11: FMS (Freeport Middle) | B11: ='I-DOEStaffing'!B15 | C11: ='I-DOEStaffing'!L15 | D11: =C11-B11 | E11: =D11/B11
A12: FHS (Freeport High) | B12: ='I-DOEStaffing'!B16 | C12: ='I-DOEStaffing'!L16 | D12: =C12-B12 | E12: =D12/B12
A13: District-wide (central) | B13: ='I-DOEStaffing'!B17 | C13: ='I-DOEStaffing'!L17 | D13: =C13-B13 | E13: =D13/B13
A15: GRAND TOTAL | B15: ='I-DOEStaffing'!B18 | C15: ='I-DOEStaffing'!L18 | D15: =C15-B15 | E15: =D15/B15
A17: 2. PES Share of District Total FTE (Trend)
A18: Compares PES's share of total staffing to its share of enrollment (~10.5%).
A19: Year | B19: PES FTE | C19: Grand Total | D19: PES Share
A20: 2016 | B20: ='I-DOEStaffing'!B11 | C20: ='I-DOEStaffing'!B18 | D20: =B20/C20
A21: 2017 | B21: ='I-DOEStaffing'!C11 | C21: ='I-DOEStaffing'!C18 | D21: =B21/C21
A22: 2018 | B22: ='I-DOEStaffing'!D11 | C22: ='I-DOEStaffing'!D18 | D22: =B22/C22
A23: 2019 | B23: ='I-DOEStaffing'!E11 | C23: ='I-DOEStaffing'!E18 | D23: =B23/C23
A24: 2020 | B24: ='I-DOEStaffing'!F11 | C24: ='I-DOEStaffing'!F18 | D24: =B24/C24
A25: 2021 | B25: ='I-DOEStaffing'!G11 | C25: ='I-DOEStaffing'!G18 | D25: =B25/C25
A26: 2022 | B26: ='I-DOEStaffing'!H11 | C26: ='I-DOEStaffing'!H18 | D26: =B26/C26
A27: 2023 | B27: ='I-DOEStaffing'!I11 | C27: ='I-DOEStaffing'!I18 | D27: =B27/C27
A28: 2024 | B28: ='I-DOEStaffing'!J11 | C28: ='I-DOEStaffing'!J18 | D28: =B28/C28
A29: 2025 | B29: ='I-DOEStaffing'!K11 | C29: ='I-DOEStaffing'!K18 | D29: =B29/C29
A30: 2026 | B30: ='I-DOEStaffing'!L11 | C30: ='I-DOEStaffing'!L18 | D30: =B30/C30
A32: PES enrollment share (FY27) | B32: ='I-Enrollment'!F12 | C32: =SUM('I-Enrollment'!F10:'I-Enrollment'!F15) | D32: =B32/C32
A33: STAFFING GAP: PES FTE share vs enrollment share | B33: =D30-D32
A35: 3. Instructional Staff (Teachers + Ed Techs + SpEd): 10-Year Change
A36: Combined Classroom Teacher + Ed Tech (I/II/III) + Special Ed Teacher FTE.
A37: School | B37: 2016 Instr | C37: 2026 Instr | D37: Change | E37: % Change
A38: PES | B38: ='I-DOEStaffing'!B23+'I-DOEStaffing'!B43+'I-DOEStaffing'!B33 | C38: ='I-DOEStaffing'!L23+'I-DOEStaffing'!L43+'I-DOEStaffing'!L33 | D38: =C38-B38 | E38: =D38/B38
A39: DCS | B39: ='I-DOEStaffing'!B24+'I-DOEStaffing'!B44+'I-DOEStaffing'!B34 | C39: ='I-DOEStaffing'!L24+'I-DOEStaffing'!L44+'I-DOEStaffing'!L34 | D39: =C39-B39 | E39: =D39/B39
A40: MSS | B40: ='I-DOEStaffing'!B25+'I-DOEStaffing'!B45+'I-DOEStaffing'!B35 | C40: ='I-DOEStaffing'!L25+'I-DOEStaffing'!L45+'I-DOEStaffing'!L35 | D40: =C40-B40 | E40: =D40/B40
A41: MLS | B41: ='I-DOEStaffing'!B26+'I-DOEStaffing'!B46+'I-DOEStaffing'!B36 | C41: ='I-DOEStaffing'!L26+'I-DOEStaffing'!L46+'I-DOEStaffing'!L36 | D41: =C41-B41 | E41: =D41/B41
A42: FMS | B42: ='I-DOEStaffing'!B27+'I-DOEStaffing'!B47+'I-DOEStaffing'!B37 | C42: ='I-DOEStaffing'!L27+'I-DOEStaffing'!L47+'I-DOEStaffing'!L37 | D42: =C42-B42 | E42: =D42/B42
A43: FHS | B43: ='I-DOEStaffing'!B28+'I-DOEStaffing'!B48+'I-DOEStaffing'!B38 | C43: ='I-DOEStaffing'!L28+'I-DOEStaffing'!L48+'I-DOEStaffing'!L38 | D43: =C43-B43 | E43: =D43/B43
A46: 4. PES Special Education Staffing (Trend)
A47: PES SpEd FTE hit 0.0 in school years 2022-23 and 2023-24.
A48: Year | B48: PES SpEd FTE | C48: District Elem Avg | D48: PES vs Avg
...

Sheet C-Equity
A1: CALC: Per-Town Equity Analysis
A3: All values are formula-driven from I-Equity inputs. Shows who pays vs. who consumes.
A5: 1. PER-STUDENT COST BY TOWN (FY27)
A6: Metric | B6: Pownal | C6: Durham | D6: Freeport | E6: RSU Average
A7: Students (attributed) | B7: ='I-Equity'!B24 | C7: ='I-Equity'!C25 | D7: ='I-Equity'!D26 | E7: ='I-Equity'!E27
A8: Local tax assessment (RLC + ALM) | B8: ='I-Equity'!B39 | C8: ='I-Equity'!C39 | D8: ='I-Equity'!D39 | E8: ='I-Equity'!E39
A9: Total funding (local + state aid) | B9: ='I-Equity'!B40 | C9: ='I-Equity'!C40 | D9: ='I-Equity'!D40 | E9: ='I-Equity'!E40
A10: LOCAL TAX PER STUDENT | B10: =B8/B7 | C10: =C8/C7 | D10: =D8/D7 | E10: =E8/E7
A11: TOTAL FUNDING PER STUDENT | B11: =B9/B7 | C11: =C9/C7 | D11: =D9/D7 | E11: =E9/E7
A13: 2A. NET POSITION: ACTUAL CONSUMPTION (from C-Consumption)
A14: Uses actual school-level budgets attributed to each town's students.
A15: PES costs are 100% Pownal. FMS/FHS split by enrollment. System pool by student count.
A16: This is the objective cost picture -- it includes PES's small-school premium.
B17: Pownal | C17: Durham | D17: Freeport
A18: Actual budget consumed (C-Consumption) | B18: ='C-Consumption'!D11 | C18: ='C-Consumption'!D19 | D18: ='C-Consumption'!D29
A19: Total contribution (local + state + shared) | B19: ='C-Revenue'!B14 | C19: ='C-Revenue'!C14 | D19: ='C-Revenue'!D14
A20: NET POSITION (revenue - consumption) | B20: =B19-B18 | C20: =C19-C18 | D20: =D19-D18
A21: Actual cost per student | B21: =B18/B7 | C21: =C18/C7 | D21: =D18/D7
A23: Pownal's deficit is REAL but modest: PES costs more per student due to fixed-cost dilution.
A24: Durham's deficit is larger. Freeport is the only net contributor.
A26: 2B. EQUALIZED ANALYSIS: What if every student cost the same?
A27: Uses RSU-wide average per-student cost. Isolates the TAX BURDEN question from
A28: the SCHOOL EFFICIENCY question. Shows whether each town pays its 'fair share'
A29: assuming equal cost per student. Contrast with 2A above for full picture.
B30: Pownal | C30: Durham | D30: Freeport
A31: RSU 5 average cost per student | B31: =E11 | C31: =E11 | D31: =E11
A32: Equalized consumption (students x avg cost) | B32: =B7*B31 | C32: =C7*C31 | D32: =D7*D31
A33: Total contribution (local + state aid) | B33: =B9 | C33: =C9 | D33: =D9
A34: EQUALIZED NET (consumed - contributed) | B34: =B32-B33 | C34: =C32-C33 | D34: =D32-D33
A35: Equalized net per household | B35: =B34/'I-Equity'!B104 | C35: =C34/'I-Equity'!C104 | D35: =D34/'I-Equity'!D104
A37: COMPARE 2A vs 2B: Pownal's actual deficit (2A) is $267K. But if every student cost
A38: the same, Pownal would be a net contributor (2B). The difference = PES's cost premium.
A39: Both are real. Presenting only one without the other is misleading.
A41: 3. COST-SHARING FORMULA IMPACT
A42: Shows how the 85/15 formula distributes ALM vs. what a pure per-student split would look like.
B43: Pownal | C43: Durham | D43: Freeport
A44: Actual ALM paid | B44: ='I-Equity'!B36 | C44: ='I-Equity'!C36 | D44: ='I-Equity'!D36
A45: ALM if split by enrollment only | B45: =(B44+C44+D44)*B7/(B7+C7+D7) | C45: =(B44+C44+D44)*C7/(B7+C7+D7) | D45: =(B44+C44+D44)*D7/(B7+C7+D7)
A46: FORMULA PENALTY (+) or BENEFIT (-) | B46: =B44-B45 | C46: =C44-C45 | D46: =D44-D45
A47: Formula penalty per household | B47: =B46/'I-Equity'!B104 | C47: =C46/'I-Equity'!C104 | D47: =D46/'I-Equity'!D104
...

Sheet C-Independence
A1: CALC: Pownal Independence Financial Analysis
A3: Four scenarios modeled: §1512 veto cost, full withdrawal, withdrawal+AOS, legal challenge.
A4: All values are formula-driven from I-Withdrawal inputs.
A6: SCENARIO A: §1512 MUNICIPAL VETO (if applicable)
A7: Under §1512, if Pownal votes to keep PES open against Board wishes,
A8: Pownal is liable for 'the amount that would be saved if the school were closed.'
A9: IMPORTANT: §1512 likely does NOT apply to Option 2 (reconfiguration, not closure).
A10: This scenario models the cost ceiling IF §1512 were successfully invoked.
A12: TRUE NET SAVINGS from closing PES (from C-FY28Paths) | B12: ='C-FY28Paths'!B36
A13: §1512 LIABILITY = savings RSU would gain | B13: =IF(B12>0,B12,0)
A14: Per-household cost (636 homes) | B14: =B13/'I-Withdrawal'!B112
A15: The TRUE NET from closing PES is approximately -$161K (a COST, not savings).
A16: If net savings are negative, there is NO amount for Pownal to reimburse under §1512.
A17: Revisited annually: Board must re-vote each year to attempt closure.
A19: SCENARIO B: FULL WITHDRAWAL (K-5 independent, tuition 6-12)
A20: Pownal withdraws from RSU 5 under Title 20-A §1466. Operates PES K-5
A21: independently. Tuitions secondary students (6-12) to Freeport or elsewhere.
A23: PES school-level operating cost | B23: ='I-Withdrawal'!B26
A24: Additional admin costs (superintendent, SpEd, etc.) | B24: ='I-Withdrawal'!B46
A25: GROSS INDEPENDENT BUDGET | B25: =SUM(B23:B24)
A27: Less: State EPS share (current) | B27: =-'I-Withdrawal'!B109
A28: Less: Isolated small school adjustment | B28: =-'I-Withdrawal'!B110
A29: NET LOCAL COST (Pownal taxpayers) | B29: =B25+B27+B28
A31: Current Pownal LOCAL tax (RLC + ALM, for comparison) | B31: ='I-Withdrawal'!B12
A32: CHANGE vs. CURRENT RSU ASSESSMENT | B32: =B29-B31
A33: Percentage increase | B33: =B32/B31
A35: New estimated mil rate (education only) | B35: =B29/'I-Withdrawal'!B111*1000
A36: Current RSU education mil rate | B36: ='I-Withdrawal'!B114
A37: Mil rate change | B37: =B35-B36
A38: Annual cost change per household (636 homes) | B38: =B32/'I-Withdrawal'!B112
A40: SCENARIO C: WITHDRAWAL + AOS (shared services)
A41: Same as Scenario B but with AOS cost sharing for admin functions.
A42: Model: AOS #94 (6 towns, shared superintendent); Bristol/South Bristol ESC.
A44: Gross independent budget (from Scenario B) | B44: =B25
A45: Less: AOS shared services savings | B45: =-'I-Withdrawal'!B57
A46: Less: State EPS + small school adjustment | B46: =B27+B28
A47: NET LOCAL COST (AOS model) | B47: =SUM(B44:B46)
A48: CHANGE vs. CURRENT RSU ASSESSMENT | B48: =B47-B31
A49: New estimated mil rate (AOS model) | B49: =B47/'I-Withdrawal'!B111*1000
A50: Annual cost change per household | B50: =B48/'I-Withdrawal'!B112
...

Sheet C-LegalAnalysis
A1: CALC: Legal & Strategic Analysis
A3: Structured assessment of Pownal's legal options. Not formula-heavy;
A4: provides decision framework for qualitative dimensions.
A6: PART 1: RECONFIGURATION vs. CLOSURE -- §1512 APPLICABILITY [Fn 30][Fn 39]
A8: STATUTORY TEXT (Title 20-A §1512(4)):
A9: "...a school closing is any action by the regional school unit board
A10: that has the effect of providing no instruction for any students at that school."
A12: Argument | B12: For §1512 Applying | C12: Against §1512 Applying | D12: Strength
A13: Plain text: 'no instruction for any students' | B13: PES K-5 students lose all instruction at PES | C13: EC/PreK students still receive instruction at the building | D13: AGAINST
A14: 'School' vs. 'building' distinction | B14: PES the K-5 school ceases to exist; EC is a new program | C14: Statute refers to 'at that school' = the physical location | D14: MIXED
A15: Legislative intent of §1512 | B15: Enacted to protect small communities from losing their schools | C15: Legislature could have written 'program' but chose 'instruction' | D15: FOR (spirit)
A16: MSAD #1 precedent (Feb 2026) [Fn 39] | B16: Different district; no court ruling; administrative practice only | C16: Pine St Elem -> PreK-Gr1 treated as reconfiguration, not closure | D16: AGAINST
A17: De facto closure doctrine | B17: Every K-5 student displaced; community loses its school in substance | C17: Courts have not applied this doctrine to Maine §1512 specifically | D17: MIXED
A18: Commissioner of Education ruling | B18: Pownal could petition for ruling; untested question = uncertainty | C18: Commissioner may defer to district's administrative discretion | D18: UNCERTAIN
A20: NET ASSESSMENT: | B20: §1512 likely does NOT block Option 2 as framed.
A21: IMPLICATION: | B21: Withdrawal (§1466) is the more reliable recourse path.
A23: PART 2: RECOURSE OPTION COMPARISON MATRIX
A24: Scale: 1 (worst) to 5 (best) for each dimension.
A26: Option | B26: Legal Strength | C26: Est. Cost | D26: Timeline | E26: Control Gained | F26: Reversibility | G26: Risk | H26: Precedent
A27: §1512 legal challenge | B27: 2 | C27: $25K-$88K | D27: 6-18 months | E27: 2 | F27: 5 | G27: 3 | H27: 2
A28: Full RSU withdrawal (§1466) | B28: 5 | C28: $70K + taxes | D28: 12-24 months | E28: 5 | F28: 3 | G28: 3 | H28: 4
A29: Withdrawal + AOS | B29: 5 | C29: $70K + taxes | D29: 12-24 months | E29: 4 | F29: 3 | G29: 2 | H29: 3
A30: Withdrawal + K-8 PES (Scenario E) | B30: 5 | C30: $70K + taxes | D30: 12-24 months | E30: 5 | F30: 2 | G30: 3 | H30: 2
A31: Advocate ALM formula change (§1481-A) | B31: 3 | C31: $5K-$15K | D31: 6-12 months | E31: 2 | F31: 5 | G31: 1 | H31: 3
A32: Leverage (threaten withdrawal) | B32: 4 | C32: $5K-$50K | D32: 3-6 months | E32: 3 | F32: 5 | G32: 1 | H32: 4
A33: Do nothing / accept | B33: 0 | C33: $0 | D33: N/A | E33: N/A | F33: N/A | G33: N/A | H33: N/A
A35: Legal Strength: 5=clear statutory right, 1=contested/weak
A36: Control: 5=full local autonomy, 1=minimal influence
A37: Risk: 5=low risk, 1=high risk. Reversibility: 5=fully reversible, 1=permanent
A38: Precedent: 5=strong Maine precedent, 1=no precedent
A40: PART 3: PARALLEL PRECEDENTS [Fn 33][Fn 34][Fn 38][Fn 39]
A42: District / Case | B42: Action | C42: Outcome | D42: Similarity to Pownal | E42: Relevance
A43: MSAD #1 / Pine Street (2026) [Fn 39] | B43: Elem -> PreK-Gr1 (reconfiguration) | C43: Treated as admin decision, not §1512 closure | D43: HIGH: same EC mandate, same building repurpose | E43: KEY
A44: SAD 75 / Harpswell (2026) [Fn 38] | B44: Community opposed closure of only school | C44: District abandoned ALL closure options | D44: HIGH: small town, community school identity | E44: HIGH
A45: Freeport / RSU 5 (2014) [Fn 33] | B45: Withdrawal petition, full agreement drafted | C45: Vote failed by 76 votes (2152-2228) | D45: DIRECT: same RSU, same legal framework | E45: KEY
A46: Dayton / RSU 23 (2014) [Fn 35] | B46: Full withdrawal, independent operation | C46: Success; mil rate 18.47->20.85; full control | D46: MODERATE: larger, different region | E46: HIGH
A47: Andover / SAD 44 (2015) [Fn 35] | B47: Full withdrawal, independent K-5 | C47: Success; mil rate 15.6->19.6; ~30 students | D47: HIGH: similar enrollment size | E47: HIGH
A48: Embden / RSU 74 (2025) [Fn 37] | B48: Withdrawal petition filed, $50K authorized | C48: Process ongoing | D48: MODERATE: rural, different region | E48: MODERATE
A50: PART 4: STRATEGIC TIMELINE & DECISION TREE
A52: Date / Window | B52: Action | C52: Prerequisite | D52: Statute
...

Sheet C-RiskModel
A1: CALC: Quantified Risk Analysis
A3: Risks that are NOT captured in the C-FY28Paths savings model.
A4: All values are formula-driven or sourced estimates. Citations in brackets.
A6: 1. PROPERTY VALUE IMPACT (Pownal) [Fn 20][Fn 27]
A7: Research: 5-15% decline in communities losing their school (Duncombe & Yinger 2010;
A8: EdWorkingPapers #22-530, 2022). Applied to Pownal's taxable valuation.
A10: Pownal taxable valuation | B10: ='I-Tax'!B13
A11: Estimated housing units (ACS 2023) [Fn 27] | B11: 636
A12: Median home value (ACS 2023) [Fn 27] | B12: 340000
A13: Total Pownal mil rate | B13: ='I-Tax'!B9
A14: Pownal RSU share of tax | B14: ='I-Tax'!B10
A15: Scenario | B15: Decline % | C15: Total Value Lost | D15: Per-Household Loss | E15: Annual Tax Revenue Lost
A16: Low (5%) | B16: 0.05 | C16: =B10*B16 | D16: =B12*B16 | E16: =C16*B13/1000
A17: Mid (10%) | B17: 0.1 | C17: =B10*B17 | D17: =B12*B17 | E17: =C17*B13/1000
A18: High (15%) | B18: 0.15 | C18: =B10*B18 | D18: =B12*B18 | E18: =C18*B13/1000
A19: RSU 5 share of mid-scenario tax loss | B19: =E17*B14
A20: Note: Tax revenue loss occurs gradually (reassessment cycles). Wealth loss is immediate.
A21: At 10% decline, median Pownal home loses ~$34,000 in value.
A23: 2. ENROLLMENT ATTRITION RISK [Fn 20][Fn 28]
A24: If PES closes, some families may leave RSU 5 (move, homeschool, private).
A25: State aid follows the student: each departure costs RSU 5 ongoing revenue.
A27: Current PES enrollment | B27: ='I-FTE'!C10
A28: Pownal state aid (FY25-26) | B28: ='I-Tax'!E41
A29: State aid per PES student | B29: =B28/B27
A30: Scenario | B30: Attrition % | C30: Students Lost | D30: Annual State Revenue Lost
A31: Low (5%) | B31: 0.05 | C31: =ROUND(B27*B31,0) | D31: =C31*B29
A32: Mid (10%) | B32: 0.1 | C32: =ROUND(B27*B32,0) | D32: =C32*B29
A33: High (20%) | B33: 0.2 | C33: =ROUND(B27*B33,0) | D33: =C33*B29
A34: Cost side does NOT shrink proportionally: fixed costs remain, class sizes are already small.
A35: At 10% attrition: 10-11 students leave, ~$50K/yr in state revenue lost to RSU 5.
A37: 3. EC OPT-OUT RISK (Path B Only)
A38: Under Path B, all PreK goes to PES in Pownal. Freeport/Durham families
A39: may refuse 22+ mile bus ride for 3-year-olds and choose private childcare instead.
A40: District PreK is voluntary -- families cannot be compelled to enroll.
A42: Total district PreK enrollment (all schools) | B42: 128 | C42: MSS 64 + DCS 48 + PES 16
A43: EC gross annual cost | B43: ='C-ECAnalysis'!B6
A44: EC cost per student (baseline) | B44: =B43/B42
A45: Scenario | B45: Opt-Out % | C45: Students Lost | D45: Cost/Remaining Student | E45: SpEd LRE Risk
A46: Low (10%) | B46: 0.1 | C46: =ROUND(B42*B46,0) | D46: =B43/(B42-C46) | E46: Moderate
A47: Mid (20%) | B47: 0.2 | C47: =ROUND(B42*B47,0) | D47: =B43/(B42-C47) | E47: Significant
...

Sheet C-FY28Projection
A1: CALC: FY28 Budget Projection
A3: Projects from FY27 adopted -> FY28 baseline -> FY28 with structural changes.
A4: FY28 is when EC mandate and any restructuring take effect (2027-2028 school year).
A6: Step 1: FY27 Adopted Budget (select scenario)
A7: SELECTED FY27 ADOPTED >> | B7: ='C-FY27Scenarios'!C20
A8: Change cell B above to test different FY27 outcomes. Default = Proposed.
A9: Conservative: ='C-FY27Scenarios'!B20 | Higher: ='C-FY27Scenarios'!D20
A11: Step 2: Cost Growth Rate (from I-CostGrowth)
A12: 3-year average growth (FY24-FY26) | B12: =AVERAGE('I-CostGrowth'!D15:'I-CostGrowth'!D17)
A13: 5-year average growth (FY22-FY26) | B13: =AVERAGE('I-CostGrowth'!D13:'I-CostGrowth'!D17)
A14: 10-year average growth (FY17-FY26) | B14: =AVERAGE('I-CostGrowth'!D8:'I-CostGrowth'!D17)
A15: SELECTED GROWTH RATE >> | B15: =B12
A16: Change cell B above to test different growth assumptions. Default = 3-year avg.
A18: Step 3: EC Mandate (FY28 new cost)
A19: EC net cost (midpoint) | B19: ='C-ECAnalysis'!D12
A21: Step 4: FY28 Baseline (no structural changes)
A22: FY28 operating (FY27 + cost growth) | B22: =B7*(1+B15)
A23: FY28 BASELINE (operating + EC) | B23: =B22+B19
A24: FY28 increase from FY27 | B24: =(B23-B7)/B7
A26: Sensitivity: FY28 Baseline by FY27 Outcome x Growth Rate
A27: FY27 Scenario | B27: 3-yr Growth | C27: 5-yr Growth | D27: 10-yr Growth
A28: Conservative | B28: ='C-FY27Scenarios'!B20*(1+B12)+B19 | C28: ='C-FY27Scenarios'!B20*(1+B13)+B19 | D28: ='C-FY27Scenarios'!B20*(1+B14)+B19
A29: Proposed | B29: ='C-FY27Scenarios'!C20*(1+B12)+B19 | C29: ='C-FY27Scenarios'!C20*(1+B13)+B19 | D29: ='C-FY27Scenarios'!C20*(1+B14)+B19
A30: Higher | B30: ='C-FY27Scenarios'!D20*(1+B12)+B19 | C30: ='C-FY27Scenarios'!D20*(1+B13)+B19 | D30: ='C-FY27Scenarios'!D20*(1+B14)+B19
A32: FY28 with Structural Changes (savings from C-FY28Paths)
A33: Path A total savings | B33: ='C-FY28Paths'!B13
A34: Path B gross savings | B34: ='C-FY28Paths'!B24
A36: FY28 with Path A | B36: =B23-B33
A37: FY28 with Path B (gross) | B37: =B23-B34
A38: Path A increase from FY27 | B38: =(B36-B7)/B7
A39: Path B increase from FY27 | B39: =(B37-B7)/B7

Sheet C-FY27Scenarios
A1: CALC: FY27 Budget Adoption Scenarios
A3: The FY27 budget goes to voters May/June 2026. Board adopts March 25.
A4: EC mandate costs and structural changes are NOT in FY27. They are FY28 decisions.
A6: FY27 Starting Point
A7: FY26 Adopted Budget | B7: ='I-Budget'!B32
A8: Initial request increase (pre-cut) | B8: ='I-FY27Reductions'!B17
A9: "Maintenance of effort" total (before cuts) | B9: =B7+B8
A10: Maint. of effort % increase | B10: =B8/B7
A12: Reductions Already in Proposed Budget
A13: Tier 1 reductions (staff positions) | B13: =SUM('I-FY27Reductions'!F24:'I-FY27Reductions'!F36)
A14: Tier 2 reductions (support positions) | B14: =SUM('I-FY27Reductions'!F40:'I-FY27Reductions'!F46)
A15: Other reductions (tech, facilities) | B15: =SUM('I-FY27Reductions'!E50:'I-FY27Reductions'!E52)
A16: TOTAL REDUCTIONS | B16: =B13+B14+B15
A18: Three Adoption Scenarios
A19: Metric | B19: Conservative | C19: Proposed | D19: Higher
A20: FY27 Budget Total | B20: =B7*1.05 | C20: ='C-Budget'!B16 | D20: ='C-Budget'!B16-B14
A21: % Increase from FY26 | B21: =(B20-B7)/B7 | C21: =(C20-B7)/B7 | D21: =(D20-B7)/B7
A22: Additional cuts beyond proposed | B22: =B20-C20 | C22: 0 | D22: =D20-C20
A23: Positions cut (T1) | B23: 13+ (T1+T2+more) | C23: 13 (T1 only) | D23: 13 (T1; T2 restored)
A24: T2 support positions | B24: Cut | C24: Cut | D24: Restored
A26: The 'Proposed' column matches the Superintendent's recommendation ($47,357,441).
A27: The 'Conservative' scenario targets 5.0% increase. Board may choose differently.
A28: The 'Higher' scenario restores T2 support positions (ed techs, instructional strategist).

Sheet C-FY28Paths
A1: CALC: FY28 Structural Scenario Comparison
A3: Path A and Path B are FY28 (2027-2028) decisions, not FY27.
A4: Savings are independent of the FY28 baseline; they come from restructuring.
A6: PATH A: Preserve & Strengthen (FY28)
A7: Item | B7: Budget Impact | C7: Source / Notes
A8: MS consolidation teacher savings | B8: =-'C-MSConsol'!B21 | C8: See C-MSConsol sheet
A9: DCS admin change (multi-community K-6) | B9: =0 | C9: Revised to $0: complexity increases (I-Assumptions)
A10: Freeport 6th transportation | B10: ='I-Assumptions'!B13*'I-Assumptions'!B12 | C10: Routes x cost/route from I-Assumptions
A11: DCS portable classrooms | B11: =0 | C11: Sections freed by 7-8 offset 6th additions
A12: Additional efficiencies (midpoint) | B12: =-AVERAGE('I-Assumptions'!B22,'I-Assumptions'!B23) | C12: Midpoint of low/high range from I-Assumptions
A13: TOTAL PATH A SAVINGS | B13: =-SUM(B8:B12)
A15: PATH B: Scenario 2 -- Gross Lens (FY28)
A16: Treats full PES instruction budget as eliminated (traditional closure analysis)
A17: Item | B17: Budget Impact | C17: Source / Notes
A18: PES instruction eliminated (gross) | B18: =-('C-Budget'!D7-'I-Budget'!D14) | C18: PES direct cost minus Art 9 facility (stays regardless)
A19: Transport: Pownal K-6 to DCS | B19: ='I-Assumptions'!B14*'I-Assumptions'!B12 | C19: Routes x cost/route from I-Assumptions
A20: Transport: Freeport PreK to PES | B20: ='I-Assumptions'!B15*'I-Assumptions'!B12 | C20: Specialized EC routes from I-Assumptions
A21: Transport: Durham PreK to PES | B21: ='I-Assumptions'!B16*'I-Assumptions'!B12 | C21: Specialized EC routes from I-Assumptions
A22: DCS multi-community coordination | B22: ='I-Assumptions'!B20 | C22: Analyst estimate from I-Assumptions
A23: PES full EC conversion (amortized) | B23: ='I-Assumptions'!B17*'I-Assumptions'!B18/'I-Assumptions'!B19 | C23: Partial cost x multiplier / years from I-Assumptions
A24: PATH B GROSS SAVINGS | B24: =-B18-SUM(B19:B23)
A26: PATH B: True Efficiency Lens -- Absorption-Adjusted (FY28)
A27: Accounts for the fact that Pownal students still need teachers at receiving schools.
A29: Marginal teacher savings (Scenario 2 total - Path A) | B29: =('I-FTE'!B42-'C-MSConsol'!B18)*'I-Assumptions'!B8 | C29: I-FTE Scenario 2 net FTE - C-MSConsol Path A FTE = marginal
A30: PES administration eliminated | B30: ='I-Budget'!D13 | C30: Full Art 7 PES from I-Budget
A31: DCS coordination cost | B31: =-'I-Assumptions'!B20 | C31: Absorbing Pownal families from I-Assumptions
A32: PES support services (partial efficiency) | B32: ='I-Budget'!D12*'I-Assumptions'!B21 | C32: Art 5 x efficiency % from I-Assumptions
A33: True Efficiency Savings | B33: =SUM(B29:B32)
A34: Minus transport (Path B) | B34: =-SUM(B19:B21)
A35: Minus PES conversion (amortized) | B35: =-B23
A36: TRUE NET SAVINGS FROM CLOSING PES | B36: =B33+B34+B35
A38: FINAL COMPARISON (FY28)
A39: Metric | B39: No Action (FY28) | C39: Path A (FY28) | D39: Path B Gross (FY28)
A40: FY28 Budget | B40: ='C-FY28Projection'!B23 | C40: ='C-FY28Projection'!B23-B13 | D40: ='C-FY28Projection'!B23-B24
A41: Increase from FY27 adopted | B41: =(B40-'C-FY28Projection'!B7)/'C-FY28Projection'!B7 | C41: =(C40-'C-FY28Projection'!B7)/'C-FY28Projection'!B7 | D41: =(D40-'C-FY28Projection'!B7)/'C-FY28Projection'!B7
A42: Savings vs. FY28 Baseline | B42: -- | C42: =B13 | D42: =B24
A43: True Net (absorption-adjusted) | B43: N/A | C43: N/A | D43: =B36

Sheet C-Enrollment
A1: CALC: Enrollment & Town-of-Origin Analysis
A3: All values are formulas referencing I-Enrollment.
A5: Cohort Averages
A6: PES avg K-5 grade size | B6: =AVERAGE('I-Enrollment'!B21:'I-Enrollment'!B26)
A7: DCS avg 7-8 grade size | B7: =AVERAGE('I-Enrollment'!B32,'I-Enrollment'!B33)
A9: Town-of-Origin at Shared Schools
A10: School | B10: Pownal (est.) | C10: Durham (est.) | D10: Freeport (est.)
A11: At FMS | B11: =ROUND(B6,0)*3 | C11: 0 | D11: ='I-Enrollment'!F14-B11
A12: At FHS | B12: =ROUND(B6,0)*4 | C12: =ROUND(B7,0)*4 | D12: ='I-Enrollment'!F15-B12-C12
A14: Total Students by Town
A15: Town | B15: Own Schools | C15: At FMS | D15: At FHS | E15: TOTAL
A16: Pownal | B16: ='I-Enrollment'!F12 | C16: =B11 | D16: =B12 | E16: =SUM(B16:D16)
A17: Durham | B17: ='I-Enrollment'!F13 | C17: 0 | D17: =C12 | E17: =SUM(B17:D17)
A18: Freeport | B18: ='I-Enrollment'!F10+'I-Enrollment'!F11 | C18: =D11 | D18: =D12 | E18: =SUM(B18:D18)
A19: DISTRICT TOTAL | E19: =E16+E17+E18

Sheet C-Budget
A1: CALC: Budget Summary & School Direct Costs
A3: All values are SUM formulas referencing I-Budget input sheet.
A5: School Direct Costs (sum of all articles per school)
A6: School | B6: DCS | C6: MSS | D6: PES | E6: MLS | F6: FMS | G6: FHS
A7: Direct Cost | B7: =SUM('I-Budget'!B9:B14) | C7: =SUM('I-Budget'!C9:C14) | D7: =SUM('I-Budget'!D9:D14) | E7: =SUM('I-Budget'!E9:E14) | F7: =SUM('I-Budget'!F9:F14) | G7: =SUM('I-Budget'!G9:G14)
A8: Per Student | B8: =B7/'I-Enrollment'!F13 | C8: =C7/'I-Enrollment'!F10 | D8: =D7/'I-Enrollment'!F12 | E8: =E7/'I-Enrollment'!F11 | F8: =F7/'I-Enrollment'!F14 | G8: =G7/'I-Enrollment'!F15
A10: System-Wide Pool
A11: System-only articles total | B11: =SUM('I-Budget'!B20:'I-Budget'!B24)
A12: SYS/K8/912/CTRL from school articles | B12: =SUM('I-Budget'!H9:'I-Budget'!H14)+SUM('I-Budget'!I9:'I-Budget'!I14)+SUM('I-Budget'!J9:'I-Budget'!J14)+SUM('I-Budget'!K9:'I-Budget'!K14)
A13: TOTAL SYSTEM-WIDE POOL | B13: =B11+B12
A15: GRAND TOTAL (Articles 1-11) | B15: =B7+C7+D7+E7+F7+G7+B13
A16: FY27 TOTAL OPERATING (+ Adult Ed) | B16: =B15+'I-Budget'!B31
A17: FY27 Increase ($) from FY26 | B17: =B16-'I-Budget'!B32
A18: FY27 Increase (%) | B18: =B17/'I-Budget'!B32

Sheet C-Consumption
A1: CALC: Budget Consumption by Town of Origin
A3: Direct costs -> 100% to town. FMS/FHS -> proportional. System -> by student count.
A5: Pownal Consumption
A6: Component | B6: School Total | C6: Share % | D6: Town's Share
A7: PES (100%) | B7: ='C-Budget'!D7 | C7: =1 | D7: =B7*C7
A8: FMS (Pownal share) | B8: ='C-Budget'!F7 | C8: ='C-Enrollment'!B11/'I-Enrollment'!F14 | D8: =B8*C8
A9: FHS (Pownal share) | B9: ='C-Budget'!G7 | C9: ='C-Enrollment'!B12/'I-Enrollment'!F15 | D9: =B9*C9
A10: System (Pownal share) | B10: ='C-Budget'!B13 | C10: ='C-Enrollment'!E16/'C-Enrollment'!E19 | D10: =B10*C10
A11: Pownal TOTAL | D11: =SUM(D7:D10)
A12: Pownal Per Student | D12: =D11/'C-Enrollment'!E16
A14: Durham Consumption
A15: Component | B15: School Total | C15: Share % | D15: Town's Share
A16: DCS (100%) | B16: ='C-Budget'!B7 | C16: =1 | D16: =B16*C16
A17: FHS (Durham share) | B17: ='C-Budget'!G7 | C17: ='C-Enrollment'!C12/'I-Enrollment'!F15 | D17: =B17*C17
A18: System (Durham share) | B18: ='C-Budget'!B13 | C18: ='C-Enrollment'!E17/'C-Enrollment'!E19 | D18: =B18*C18
A19: Durham TOTAL | D19: =SUM(D16:D18)
A20: Durham Per Student | D20: =D19/'C-Enrollment'!E17
A22: Freeport Consumption
A23: Component | B23: School Total | C23: Share % | D23: Town's Share
A24: MSS (100%) | B24: ='C-Budget'!C7 | C24: =1 | D24: =B24*C24
A25: MLS (100%) | B25: ='C-Budget'!E7 | C25: =1 | D25: =B25*C25
A26: FMS (Freeport share) | B26: ='C-Budget'!F7 | C26: ='C-Enrollment'!D11/'I-Enrollment'!F14 | D26: =B26*C26
A27: FHS (Freeport share) | B27: ='C-Budget'!G7 | C27: ='C-Enrollment'!D12/'I-Enrollment'!F15 | D27: =B27*C27
A28: System (Freeport share) | B28: ='C-Budget'!B13 | C28: ='C-Enrollment'!E18/'C-Enrollment'!E19 | D28: =B28*C28
A29: Freeport TOTAL | D29: =SUM(D24:D28)
A30: Freeport Per Student | D30: =D29/'C-Enrollment'!E18
A33: Integrity Check
A34: Sum of Town Consumption | D34: =D11+D19+D29
A35: Budget Total (should match) | D35: ='C-Budget'!B15
A36: Variance | D36: =D34-D35

Sheet C-Revenue
A1: CALC: Revenue & Net Fiscal Position
A3: All values reference I-Revenue and C-Enrollment.
A5: ALM Percentage (computed)
A6: Pownal ALM % | B6: ='I-Revenue'!B10/('I-Revenue'!B10+'I-Revenue'!C10+'I-Revenue'!D10)
A7: Durham ALM % | B7: ='I-Revenue'!C10/('I-Revenue'!B10+'I-Revenue'!C10+'I-Revenue'!D10)
A8: Freeport ALM % | B8: ='I-Revenue'!D10/('I-Revenue'!B10+'I-Revenue'!C10+'I-Revenue'!D10)
A10: Total Revenue by Town
A11: Component | B11: Pownal | C11: Durham | D11: Freeport
A12: Total Contribution | B12: =SUM('I-Revenue'!B9:'I-Revenue'!B12) | C12: =SUM('I-Revenue'!C9:'I-Revenue'!C12) | D12: =SUM('I-Revenue'!D9:'I-Revenue'!D12)
A13: Shared Revenue | B13: ='I-Revenue'!B14*B6 | C13: ='I-Revenue'!B14*B7 | D13: ='I-Revenue'!B14*B8
A14: TOTAL REVENUE | B14: =B12+B13 | C14: =C12+C13 | D14: =D12+D13
A16: Net Fiscal Position
A17: Town | B17: Revenue | C17: Consumption | D17: Net Position | E17: Students | F17: Rev/Stu | G17: Cost/Stu
A18: Pownal | B18: =B14 | C18: ='C-Consumption'!D11 | D18: =B18-C18 | E18: ='C-Enrollment'!E16 | F18: =B18/E18 | G18: =C18/E18
A19: Durham | B19: =C14 | C19: ='C-Consumption'!D19 | D19: =B19-C19 | E19: ='C-Enrollment'!E17 | F19: =B19/E19 | G19: =C19/E19
A20: Freeport | B20: =D14 | C20: ='C-Consumption'!D29 | D20: =B20-C20 | E20: ='C-Enrollment'!E18 | F20: =B20/E20 | G20: =C20/E20

Sheet C-Tax
A1: CALC: Tax Analysis
A3: All values reference I-Tax and I-Revenue input sheets.
A5: RSU Net Tax Impact (RLC + ALM + Non-Shared Debt)
A6: Pownal | B6: ='I-Revenue'!B9+'I-Revenue'!B10+'I-Revenue'!B12
A7: Durham | B7: ='I-Revenue'!C9+'I-Revenue'!C10+'I-Revenue'!C12
A8: Freeport | B8: ='I-Revenue'!D9+'I-Revenue'!D10+'I-Revenue'!D12
A10: Equalized School Mil Rates
A11: Town | B11: RSU Net Tax | C11: State Val | D11: Eq School Mil | E11: Local Mil | F11: Assessment Ratio
A12: Pownal | B12: =B6 | C12: ='I-Tax'!B14 | D12: =B12/C12*1000 | E12: =B12/'I-Tax'!B13*1000 | F12: ='I-Tax'!B13/'I-Tax'!B14
A13: Durham | B13: =B7 | C13: ='I-Tax'!B35 | D13: =B13/C13*1000 | E13: =B13/'I-Tax'!B34*1000 | F13: ='I-Tax'!B34/'I-Tax'!B35
A14: Freeport | B14: =B8 | C14: ='I-Tax'!B25 | D14: =B14/C14*1000 | E14: =B14/'I-Tax'!B24*1000 | F14: ='I-Tax'!B24/'I-Tax'!B25
A16: Per-Student Tax Burden
A17: Town | B17: RSU Net Tax | C17: Students | D17: Tax/Student
A18: Pownal | B18: =B6 | C18: ='C-Enrollment'!E16 | D18: =B18/C18
A19: Durham | B19: =B7 | C19: ='C-Enrollment'!E17 | D19: =B19/C19
A20: Freeport | B20: =B8 | C20: ='C-Enrollment'!E18 | D20: =B20/C20

Sheet C-CostPremium
A1: CALC: PES Per-Student Cost Premium
A3: Compares PES per-student cost vs average of DCS, MSS, MLS from I-Budget.
A5: Article | B5: PES $/Stu | C5: DCS $/Stu | D5: MSS $/Stu | E5: MLS $/Stu | F5: Other Avg | G5: PES Premium
A6: Art 1 - Regular Instr. | B6: ='I-Budget'!D9/'I-Enrollment'!F12 | C6: ='I-Budget'!B9/'I-Enrollment'!F13 | D6: ='I-Budget'!C9/'I-Enrollment'!F10 | E6: ='I-Budget'!E9/'I-Enrollment'!F11 | F6: =AVERAGE(C6:E6) | G6: =B6-F6
A7: Art 2 - Special Ed | B7: ='I-Budget'!D10/'I-Enrollment'!F12 | C7: ='I-Budget'!B10/'I-Enrollment'!F13 | D7: ='I-Budget'!C10/'I-Enrollment'!F10 | E7: ='I-Budget'!E10/'I-Enrollment'!F11 | F7: =AVERAGE(C7:E7) | G7: =B7-F7
A8: Art 4 - Other Instr. | B8: ='I-Budget'!D11/'I-Enrollment'!F12 | C8: ='I-Budget'!B11/'I-Enrollment'!F13 | D8: ='I-Budget'!C11/'I-Enrollment'!F10 | E8: ='I-Budget'!E11/'I-Enrollment'!F11 | F8: =AVERAGE(C8:E8) | G8: =B8-F8
A9: Art 5 - Student Support | B9: ='I-Budget'!D12/'I-Enrollment'!F12 | C9: ='I-Budget'!B12/'I-Enrollment'!F13 | D9: ='I-Budget'!C12/'I-Enrollment'!F10 | E9: ='I-Budget'!E12/'I-Enrollment'!F11 | F9: =AVERAGE(C9:E9) | G9: =B9-F9
A10: Art 7 - Administration | B10: ='I-Budget'!D13/'I-Enrollment'!F12 | C10: ='I-Budget'!B13/'I-Enrollment'!F13 | D10: ='I-Budget'!C13/'I-Enrollment'!F10 | E10: ='I-Budget'!E13/'I-Enrollment'!F11 | F10: =AVERAGE(C10:E10) | G10: =B10-F10
A11: Art 9 - Facilities | B11: ='I-Budget'!D14/'I-Enrollment'!F12 | C11: ='I-Budget'!B14/'I-Enrollment'!F13 | D11: ='I-Budget'!C14/'I-Enrollment'!F10 | E11: ='I-Budget'!E14/'I-Enrollment'!F11 | F11: =AVERAGE(C11:E11) | G11: =B11-F11
A12: TOTAL | B12: =SUM(B6:B11) | F12: =SUM(F6:F11) | G12: =B12-F12
A14: Total Gap (premium x PES enrollment) | B14: =G12*'I-Enrollment'!F12

Sheet C-MSConsol
A1: CALC: Middle School Consolidation
A3: References I-FTE for current staffing, I-Enrollment for student counts, I-Assumptions for targets.
A5: Student Movement
A6: Pownal 6th graders (est.) | B6: =ROUND('C-Enrollment'!B6,0)
A7: Freeport 6th graders (est.) | B7: ='I-Enrollment'!B38-B6
A8: New FMS total (district 7-8) | B8: ='I-Enrollment'!B39+'I-Enrollment'!B40+'I-Enrollment'!B32+'I-Enrollment'!B33
A9: New DCS 6th total (district-wide) | B9: ='I-Enrollment'!B31+'I-Enrollment'!B38
A11: Staffing Impact
A12: Grade Level | B12: Current FTE | C12: Proposed FTE | D12: Change
A13: Grades 7-8 | B13: ='I-FTE'!C22+'I-FTE'!C28 | C13: =B8/'I-Assumptions'!B9 | D13: =C13-B13
A14: Grade 6 | B14: ='I-FTE'!C21+'I-FTE'!C27 | C14: =B9/'I-Assumptions'!B10 | D14: =C14-B14
A15: NET | B15: =B13+B14 | C15: =C13+C14 | D15: =C15-B15
A17: Financial Summary
A18: Net FTE Saved | B18: =-D15
A19: Teacher Savings | B19: =B18*'I-Assumptions'!B8
A20: Extracurricular Savings | B20: ='I-Assumptions'!B11
A21: TOTAL MS CONSOLIDATION SAVINGS | B21: =B19+B20

Sheet C-ECAnalysis
A1: CALC: EC Net Cost Analysis
A3: References I-ECCosts for staff costs and offsets.
A4: NOTE: EC costs are FY28 expenses (begin July 2027), not FY27.
A6: Option 1 Gross Cost | B6: =SUM('I-ECCosts'!D12:'I-ECCosts'!D19)+'I-ECCosts'!D21
A7: Offsets (high -> low net cost) | B7: =SUM('I-ECCosts'!C29:'I-ECCosts'!C31)
A8: Offsets (low -> high net cost) | B8: =SUM('I-ECCosts'!B29:'I-ECCosts'!B31)
A9: Offsets (midpoint) | B9: =AVERAGE(B7,B8)
B11: Low | C11: High | D11: Midpoint
A12: NET EC COST (annual, FY28+) | B12: =B6-B7 | C12: =B6-B8 | D12: =B6-B9

Sheet I-Equity
A1: INPUT: Per-Town Equity & Cost-Sharing Data
A3: Data for analyzing fairness of RSU 5 cost allocation across Pownal, Durham, and Freeport.
A4: Combines enrollment attribution, assessment history, EPS allocation, and cost-sharing formula.
A5: NOTE: FMS and FHS serve multiple towns; per-town estimates use cohort-based attribution.
A6: Sources cited per item. See Sources sheet for full citations.
A8: 1. ENROLLMENT BY TOWN (FY27 Projected) [Fn 1]
A9: SOURCE: FY27 Budget Handbook enrollment table [Fn 1], PES grade data [Fn 1].
A10: PES and DCS are single-town schools. MSS and MLS serve Freeport only.
A11: FMS (6-8) serves Freeport + Pownal. FHS (9-12) serves all three towns.
A12: Secondary attribution is ESTIMATED from cohort sizes at each town's elementary school.
A13: School / Segment | B13: Pownal | C13: Durham | D13: Freeport | E13: Total | F13: Basis
A14: PES (PreK-5) | B14: 105 | C14: 0 | D14: 0 | E14: 105 | F14: PES enrollment, 100% Pownal [Fn 1]
A15: DCS (PreK-8) | B15: 0 | C15: 467 | D15: 0 | E15: 467 | F15: DCS enrollment, 100% Durham [Fn 1]
A16: MSS (PreK-2) | B16: 0 | C16: 0 | D16: 274 | E16: 274 | F16: MSS enrollment, 100% Freeport [Fn 1]
A17: MLS (3-5) | B17: 0 | C17: 0 | D17: 264 | E17: 264 | F17: MLS enrollment, 100% Freeport [Fn 1]
A18: FMS (6-8) - Pownal residents | B18: 45 | C18: 0 | D18: 0 | E18: 45 | F18: Est: PES avg 15/grade × 3 grades [Fn 1]
A19: FMS (6-8) - Freeport residents | B19: 0 | C19: 0 | D19: 261 | E19: 261 | F19: 306 total FMS minus 45 Pownal est.
A20: FHS (9-12) - Pownal residents | B20: 55 | C20: 0 | D20: 0 | E20: 55 | F20: Est: PES avg cohort × 4 grades [Fn 1]
A21: FHS (9-12) - Durham residents | B21: 0 | C21: 225 | D21: 0 | E21: 225 | F21: Est: DCS avg ~56/grade × 4 grades [Fn 1]
A22: FHS (9-12) - Freeport residents | B22: 0 | C22: 0 | D22: 274 | E22: 274 | F22: 554 total FHS minus 55 POW minus 225 DUR
A24: TOTAL STUDENTS - Pownal | B24: =SUM(B14:B22)
A25: TOTAL STUDENTS - Durham | C25: =SUM(C14:C22)
A26: TOTAL STUDENTS - Freeport | D26: =SUM(D14:D22)
A27: TOTAL STUDENTS - All Towns | E27: =SUM(E14:E22)
A29: 2. FY27 PROPOSED ASSESSMENT BY TOWN [Fn 3]
A30: SOURCE: FY27 Budget Handbook, pp.9-10, Budget Impact Summary (02/11/2026) [Fn 3]
A31: RLC = Required Local Contribution (set by Maine DOE via EPS formula).
A32: ALM = Additional Local Monies (allocated by RSU 5 cost-sharing formula).
A33: State Aid = EPS state subsidy (flows directly to RSU, not through town).
A34: Component | B34: Pownal | C34: Durham | D34: Freeport | E34: Total
A35: Required Local Contribution (RLC) | B35: 2257247 | C35: 3910950 | D35: 14173184 | E35: =B35+C35+D35
A36: Additional Local Monies (ALM) | B36: 2190978 | C36: 3724663 | D36: 11473075 | E36: =B36+C36+D36
A37: State Aid | B37: 567180 | C37: 5991564 | D37: 1463889 | E37: =B37+C37+D37
A39: LOCAL TAX ASSESSMENT (RLC + ALM) | B39: =B35+B36 | C39: =C35+C36 | D39: =D35+D36 | E39: =E35+E36
A40: TOTAL FUNDING (Local + State Aid) | B40: =B39+B37 | C40: =C39+C37 | D40: =D39+D37 | E40: =E39+E37
A42: 3. EPS ALLOCATION BY TOWN (FY25-26) [Fn 8]
A43: SOURCE: Maine DOE Warrant Article F, FY25-26 Education Subsidy (09/09/2025) [Fn 8]
A44: EPS allocation = the state's calculated cost of educating each town's students.
A45: Local contribution = minimum local share required to receive state subsidy.
A46: State share = EPS allocation minus local contribution.
...

Sheet I-Withdrawal
A1: INPUT: RSU 5 Withdrawal & Independence Data
A3: Data for modeling Pownal's options if RSU 5 proceeds with PES conversion.
A4: Includes current RSU assessment, independent operating estimates, tuition rates,
A5: EPS allocations, withdrawal process costs, and legal challenge estimates.
A6: Sources cited per item. See Sources sheet for full citations.
A8: 1. POWNAL'S CURRENT RSU 5 POSITION [Fn 3][Fn 8]
A9: Item | B9: Value | C9: Source
A10: Pownal Required Local Contribution (RLC) | B10: 2257247 | C10: FY27 Budget Handbook [Fn 3]
A11: Pownal Additional Local Monies (ALM) | B11: 2190978 | C11: FY27 Budget Handbook [Fn 3]
A12: Pownal LOCAL Tax (RLC + ALM) | B12: =B10+B11 | C12: What Pownal taxpayers actually pay
A13: Pownal State Aid | B13: 567180 | C13: FY27 Budget Handbook [Fn 3]
A14: Pownal Total Contribution (local + state) | B14: 5015405 | C14: RLC + ALM + State Aid [Fn 3]
A15: Pownal Share of RSU 5 Budget | B15: 0.106 | C15: ~10.6% of $47.36M total [Fn 25]
A17: 2. PES CURRENT OPERATING COST [Fn 2]
A18: PES budget detail from I-Budget sheet. These are the costs RSU 5 currently spends on PES.
A19: Budget Article | B19: PES Amount | C19: Source
A20: Art 1 - Regular Instruction | B20: 1196683 | C20: I-Budget [Fn 2]
A21: Art 2 - Special Education | B21: 329115 | C21: I-Budget [Fn 2]
A22: Art 4 - Other Instruction | B22: 13125 | C22: I-Budget [Fn 2]
A23: Art 5 - Student & Staff Support | B23: 219819 | C23: I-Budget [Fn 2]
A24: Art 7 - School Administration | B24: 257979 | C24: I-Budget [Fn 2]
A25: Art 9 - Facilities & Maintenance | B25: 253384 | C25: I-Budget [Fn 2]
A26: PES School-Level Subtotal | B26: =SUM(B20:B25)
A27: PES Enrollment (FY27) | B27: 89 | C27: Budget Handbook [Fn 1]
A28: PES Cost Per Student | B28: =B26/B27
A30: 3. INDEPENDENT OPERATION: ADDITIONAL COSTS [Fn 37][Fn 35]
A31: Costs Pownal would incur beyond PES school-level budget if operating independently.
A32: Estimates derived from comparable Maine independent school units and state averages.
A33: SOURCE: Maine Monitor withdrawal explainer [Fn 37]; DOE tuition rates [Fn 36].
A34: Cost Category | B34: Annual Estimate | C34: Basis / Source
A35: Superintendent (shared or part-time) | B35: 95000 | C35: 50% of ~$190K salary+benefits; comparable AOS arrangements [Fn 37]
A36: Business Manager / Finance | B36: 75000 | C36: Part-time or shared; required for SAU reporting
A37: SpEd Director (shared or contracted) | B37: 65000 | C37: 50% of ~$130K; can share via AOS or contract with neighboring SAU
A38: Central office support (HR, payroll, records) | B38: 55000 | C38: 1 FTE clerical + systems; comparable small-town SAUs
A39: Transportation (K-5 PES routes) | B39: 225000 | C39: 3 routes at $75K/route; current RSU 5 Pownal allocation est.
A40: Transportation (6-12 secondary routes) | B40: 100000 | C40: Est. 1-2 routes Pownal->Freeport, ~12mi each way, $50-75K/route
A41: Secondary tuition (6-12) | B41: =B76*B64 | C41: =total secondary students x state avg rate [Fn 36]
A42: Facilities/maintenance supplement | B42: 50000 | C42: Beyond Art 9 in PES budget; insurance, grounds, capital reserve
A43: Curriculum, technology, assessment | B43: 40000 | C43: Standardized testing, materials, IT support
A44: Board/governance costs | B44: 15000 | C44: Legal counsel retainer, meeting costs, elections
...

Sheet I-DOEStaffing
A1: INPUT: Maine DOE Historical Staffing (FTE)
A3: SOURCE: Maine DOE NEO Staff Historical Dec 1 Headcount Data [Fn 45]
A4: Dataset: [Fed_Reporting].Reports.StaffHistoricalDec1, SAUOrgId=1449 (RSU 5)
A5: Requested by Mark Dohle (03/04/2026); fulfilled by Maine DOE Data Team (03/09/2026).
A6: DOE Issue #66636. Raw data file: 'MDohle RSU 5 Staff by FTE.xlsx'
A7: FTE = total sum of time staff is employed, as reported Dec 1 each year.
A9: 1. Total FTE by School (All Position Categories)
A10: School | B10: 2016 | C10: 2017 | D10: 2018 | E10: 2019 | F10: 2020 | G10: 2021 | H10: 2022 | I10: 2023 | J10: 2024 | K10: 2025 | L10: 2026
A11: PES (Pownal Elementary) | B11: 26.3 | C11: 33.8 | D11: 29.6 | E11: 28 | F11: 27.7 | G11: 27.3 | H11: 24.5 | I11: 22.5 | J11: 22.9 | K11: 21.5 | L11: 24.2
A12: DCS (Durham Community) | B12: 71.6 | C12: 88 | D12: 84.8 | E12: 92.1 | F12: 94.2 | G12: 93 | H12: 87.6 | I12: 83.5 | J12: 78.4 | K12: 88.8 | L12: 85.7
A13: MSS (Morse Street) | B13: 42.1 | C13: 42.7 | D13: 50.5 | E13: 57.1 | F13: 55.7 | G13: 55.5 | H13: 60.8 | I13: 58.5 | J13: 59.8 | K13: 64.7 | L13: 55
A14: MLS (Mast Landing) | B14: 37 | C14: 48.2 | D14: 46.4 | E14: 50.2 | F14: 55.2 | G14: 46.4 | H14: 50.5 | I14: 49.1 | J14: 45.7 | K14: 53.8 | L14: 50.5
A15: FMS (Freeport Middle) | B15: 63.9 | C15: 71.4 | D15: 75.7 | E15: 74.6 | F15: 71.7 | G15: 58.9 | H15: 67.8 | I15: 69.7 | J15: 62.8 | K15: 64.9 | L15: 66.4
A16: FHS (Freeport High) | B16: 102 | C16: 112.5 | D16: 106 | E16: 124.1 | F16: 123.1 | G16: 112.4 | H16: 100.4 | I16: 100 | J16: 97.4 | K16: 108 | L16: 98.5
A17: District-wide | B17: 103.9 | C17: 123.4 | D17: 111.4 | E17: 125.4 | F17: 115.4 | G17: 118.9 | H17: 119.8 | I17: 129.9 | J17: 116.2 | K17: 144.3 | L17: 139.8
A18: GRAND TOTAL | B18: =SUM(B11:B17) | C18: =SUM(C11:C17) | D18: =SUM(D11:D17) | E18: =SUM(E11:E17) | F18: =SUM(F11:F17) | G18: =SUM(G11:G17) | H18: =SUM(H11:H17) | I18: =SUM(I11:I17) | ... L18: =SUM(L11:L17)
A20: 2. Classroom Teacher FTE by School
A21: DOE 'Classroom Teacher' includes all certified teaching positions (core + specialists).
A22: School | B22: 2016 | C22: 2017 | D22: 2018 | E22: 2019 | F22: 2020 | G22: 2021 | H22: 2022 | I22: 2023 | J22: 2024 | K22: 2025 | L22: 2026
A23: PES | B23: 10.4 | C23: 10.2 | D23: 6.3 | E23: 8.3 | F23: 8.7 | G23: 10.2 | H23: 9.2 | I23: 10.8 | J23: 9.8 | K23: 10.2 | L23: 9.3
A24: DCS | B24: 26 | C24: 31.3 | D24: 25.5 | E24: 30 | F24: 31 | G24: 34 | H24: 33 | I24: 33.5 | J24: 34.5 | K24: 34.5 | L24: 35.5
A25: MSS | B25: 16 | C25: 16.2 | D25: 16.3 | E25: 18.5 | F25: 19.8 | G25: 20.8 | H25: 21.2 | I25: 20.6 | J25: 21.6 | K25: 21.2 | L25: 19.2
A26: MLS | B26: 14.6 | C26: 17.6 | D26: 16.5 | E26: 17.7 | F26: 16.7 | G26: 17.6 | H26: 16.6 | I26: 17.6 | J26: 16.6 | K26: 19.6 | L26: 19.6
A27: FMS | B27: 25.5 | C27: 26.2 | D27: 24.5 | E27: 24.5 | F27: 23.9 | G27: 22.1 | H27: 23.5 | I27: 23.5 | J27: 24 | K27: 23.5 | L27: 23.3
A28: FHS | B28: 37 | C28: 39.1 | D28: 34.5 | E28: 38.6 | F28: 40.7 | G28: 42.2 | H28: 42.2 | I28: 42.7 | J28: 42.7 | K28: 42.6 | L28: 41.7
A30: 3. Special Education Teacher FTE by School
A31: Includes Special Education Teacher + Special Education Consultant positions.
A32: School | B32: 2016 | C32: 2017 | D32: 2018 | E32: 2019 | F32: 2020 | G32: 2021 | H32: 2022 | I32: 2023 | J32: 2024 | K32: 2025 | L32: 2026
A33: PES | B33: 1.8 | C33: 1.8 | D33: 2 | E33: 0.5 | F33: 1 | G33: 1 | H33: 1 | I33: 0 | J33: 0 | K33: 1 | L33: 1.5
A34: DCS | B34: 4 | C34: 5 | D34: 5 | E34: 4.5 | F34: 4 | G34: 4 | H34: 4 | I34: 4 | J34: 4 | K34: 5 | L34: 6.1
A35: MSS | B35: 2 | C35: 2 | D35: 2 | E35: 3 | F35: 3 | G35: 3 | H35: 3 | I35: 4.1 | J35: 4.1 | K35: 6 | L35: 4.9
A36: MLS | B36: 2 | C36: 2 | D36: 3 | E36: 2 | F36: 3 | G36: 3 | H36: 3 | I36: 3 | J36: 4 | K36: 4 | L36: 4.5
A37: FMS | B37: 4 | C37: 4 | D37: 4 | E37: 4 | F37: 3 | G37: 4 | H37: 4 | I37: 4 | J37: 4 | K37: 4 | L37: 4.5
A38: FHS | B38: 5 | C38: 6 | D38: 5 | E38: 5 | F38: 5 | G38: 5 | H38: 4 | I38: 4 | J38: 4 | K38: 5 | L38: 4.5
A40: 4. Ed Tech FTE (I + II + III + Library/Media) by School
A41: Includes Ed Tech I, Ed Tech II, Ed Tech II - Library/Media, Ed Tech III.
A42: School | B42: 2016 | C42: 2017 | D42: 2018 | E42: 2019 | F42: 2020 | G42: 2021 | H42: 2022 | I42: 2023 | J42: 2024 | K42: 2025 | L42: 2026
A43: PES | B43: 6.4 | C43: 7.4 | D43: 5.7 | E43: 4.7 | F43: 4.2 | G43: 4.5 | H43: 3.1 | I43: 2.1 | J43: 5.1 | K43: 3.1 | L43: 4
A44: DCS | B44: 10 | C44: 11 | D44: 15 | E44: 13 | F44: 14 | G44: 14.5 | H44: 16 | I44: 14 | J44: 12 | K44: 13 | L44: 13.5
A45: MSS | B45: 8 | C45: 8 | D45: 13.4 | E45: 12.4 | F45: 12.5 | G45: 14 | H45: 15 | I45: 14.6 | J45: 16.6 | K45: 15 | L45: 12
...

Sheet I-Enrollment
A1: INPUT: Enrollment Data
A3: SOURCE: FY27 Budget Handbook, RSU 5 Superintendent's Office, pp.3-4 (02/11/2026) [Fn 1]
A4: "Projected Enrollment 2026-2027" table and Teacher/Class Size table.
A5: URL: https://resources.finalsite.net/images/v1770852522/rsu5org/ytm49nnwpbrzi4oiwg4i/FY27BUDGETHANDBOOK02112026.pdf
A6: All enrollment figures are October 1 counts as reported by RSU 5.
A8: 1A. Historical Enrollment by School
A9: School | B9: Grades | C9: Oct 2023 | D9: Oct 2024 | E9: Oct 2025 | F9: Oct 2026P
A10: MSS (Morse Street) | B10: PreK-2 | C10: 316 | D10: 288 | E10: 275 | F10: 274
A11: MLS (Mast Landing) | B11: 3-5 | C11: 281 | D11: 266 | E11: 282 | F11: 264
A12: PES (Pownal Elementary) | B12: PreK-5 | C12: 89 | D12: 97 | E12: 98 | F12: 105
A13: DCS (Durham Community) | B13: PreK-8 | C13: 473 | D13: 466 | E13: 453 | F13: 467
A14: FMS (Freeport Middle) | B14: 6-8 | C14: 293 | D14: 288 | E14: 286 | F14: 306
A15: FHS (Freeport High) | B15: 9-12 | C15: 632 | D15: 592 | E15: 577 | F15: 554
A17: 1B. PES Grade-Level Enrollment (for cohort estimation)
A18: Source: same Budget Handbook, Teacher/Class Size table, p.4
A19: Grade | B19: Students | C19: Teachers
A20: PreK | B20: 16 | C20: 0.5
A21: K | B21: 14 | C21: 1
A22: 1 | B22: 14 | C22: 1
A23: 2 | B23: 13 | C23: 1
A24: 3 | B24: 17 | C24: 1
A25: 4 | B25: 13 | C25: 1
A26: 5 | B26: 18 | C26: 1
A28: 1C. DCS Middle-Grade Enrollment
A29: Source: same Budget Handbook, Teacher/Class Size table
A30: Grade | B30: Students
A31: Grade 6 | B31: 41
A32: Grade 7 | B32: 46
A33: Grade 8 | B33: 54
A35: 1D. FMS Grade-Level Enrollment
A36: Source: same Budget Handbook. FMS 6th total includes Pownal + Freeport students.
A37: Grade | B37: Students
A38: Grade 6 (all towns) | B38: 116
A39: Grade 7 | B39: 95
A40: Grade 8 | B40: 95

Sheet I-Budget
A1: INPUT: FY27 Proposed Budget by Cost Center
A3: SOURCE: FY27 Superintendent's Proposed Budget Articles, 89-page line-item detail (02/11/2026) [Fn 2]
A4: URL: https://resources.finalsite.net/images/v1770852540/rsu5org/spzuwjskm8vh3t9bjck8/2026-2027SuperintendentsRecommendedBudgetArticlesforWebsite02112026.pdf
A5: Each cell value is the total for that school x article combination as reported in the budget articles.
A6: SYS = system-wide allocation; K8 = K-8 allocation; 912 = 9-12 allocation; CTRL = central office.
A8: Article | B8: DCS | C8: MSS | D8: PES | E8: MLS | F8: FMS | G8: FHS | H8: SYS | I8: K8 | J8: 912 | K8: CTRL
A9: Art 1 - Regular Instruction | B9: 4611862 | C9: 2506278 | D9: 1196683 | E9: 2338114 | F9: 3201928 | G9: 5310140 | H9: 0 | I9: 420852 | J9: 287336 | K9: 0
A10: Art 2 - Special Education | B10: 1553029 | C10: 1037964 | D10: 329115 | E10: 971107 | F10: 1062320 | G10: 1013463 | H10: 836683 | I10: 347140 | J10: 359601 | K10: 0
A11: Art 4 - Other Instruction | B11: 90140 | C11: 7710 | D11: 13125 | E11: 12626 | F11: 277908 | G11: 769494 | H11: 0 | I11: 1536 | J11: 0 | K11: 0
A12: Art 5 - Student & Staff Support | B12: 581386 | C12: 400046 | D12: 219819 | E12: 363844 | F12: 490321 | G12: 1061829 | H12: 1523668 | I12: 249421 | J12: 16032 | K12: 0
A13: Art 7 - School Administration | B13: 515193 | C13: 421185 | D13: 257979 | E13: 400206 | F13: 462558 | G13: 580903 | H13: 0 | I13: 0 | J13: 0 | K13: 0
A14: Art 9 - Facilities & Maintenance | B14: 683965 | C14: 569640 | D14: 253384 | E14: 482373 | F14: 641780 | G14: 1745609 | H14: 1564602 | I14: 0 | J14: 0 | K14: 52424
A16: System-Only Articles (not allocated to individual schools)
A17: SOURCE: Same 89-page budget articles document [Fn 2].
A18: These articles are district-wide and have no school-level breakdown.
A19: Article | B19: Amount
A20: Art 3 - CTE | B20: 337282
A21: Art 6 - System Administration | B21: 1308008
A22: Art 8 - Transportation | B22: 2388457
A23: Art 10 - Debt Service | B23: 1071577
A24: Art 11 - All Other | B24: 69796
A26: Budget Totals
A27: FY27 total: Revised Budget Handbook 02/11/2026. Articles 1-11 + Adult Ed = $47,357,441 [Fn 25]
A28: URL: https://www.rsu5.org/fs/resource-manager/view/78dce71e-a8e6-4435-b33f-9746e8541a3a
A29: FY26 adopted: $44,455,929, approved by voters 06/10/2025 (817 Yes, 494 No) [Fn 9]
A30: Item | B30: Amount
A31: Adult Education | B31: 88000
A32: FY26 Adopted Budget | B32: 44455929

Sheet I-Revenue
A1: INPUT: Revenue by Town (FY27 Proposed)
A3: SOURCE: FY27 Budget Handbook, RSU 5, Budget Impact Summary pp.9-10 (02/11/2026) [Fn 3]
A4: URL: https://resources.finalsite.net/images/v1770852522/rsu5org/ytm49nnwpbrzi4oiwg4i/FY27BUDGETHANDBOOK02112026.pdf
A5: Revenue components as reported on the cost-sharing summary page.
A6: Shared Revenue total from same page; allocated by ALM percentage.
A8: Component | B8: Pownal | C8: Durham | D8: Freeport
A9: Required Local Contribution (RLC) | B9: 2257247.3 | C9: 3910950.1 | D9: 14173184
A10: Additional Local Monies (ALM) | B10: 2190978.3 | C10: 3724663.2 | D10: 11473075
A11: State Aid | B11: 567179.79 | C11: 5991563.9 | D11: 1463888.5
A12: Non-Shared Debt Service | B12: 0 | C12: 117175.57 | D12: 0
A14: Total Shared Revenue | B14: 1431699.1
A15: Shared revenue is allocated by each town's ALM percentage (computed on Calc sheets).

Sheet I-Tax
A1: INPUT: Tax Rates & Property Valuations
A3: POWNAL
A4: SOURCE: Pownal FY26 Real Estate Tax Commitment Book, committed 07/29/2025 [Fn 4]
A5: Tax rate: $15.300/thousand. Town of Pownal Assessor, https://www.pownalmaine.org/
A6: Tax breakdown: RSU 58.4%, County 3.3%, Town 38.3% [Fn 12].
A7: State valuation: $399,866,667 [Fn 3].
A8: Item | B8: Value | C8: Source Detail
A9: Total Mil Rate | B9: 15.3 | C9: Commitment Book [Fn 4]
A10: RSU Share of Tax | B10: 0.584 | C10: Municipal records [Fn 12]
A11: County Share of Tax | B11: 0.033 | C11: Municipal records [Fn 12]
A12: Town Share of Tax | B12: 0.383 | C12: Municipal records [Fn 12]
A13: Taxable Valuation | B13: 392398240 | C13: Commitment Book final total [Fn 4]
A14: State Valuation | B14: 399866667 | C14: Budget Handbook p.10 [Fn 3]
A16: FREEPORT
A17: SOURCE: Freeport FY26 tax rate $13.85/thousand at 100% assessment ratio [Fn 5]
A18: Freeport Assessor, committed 09/15/2025. https://www.freeportmaine.com/158/Assessor
A19: Component breakdown from FY25 Budget Presentation (FY26 detail not yet public) [Fn 6]
A20: Valuations from FY27 Budget Handbook [Fn 3].
A21: Item | B21: Value | C21: Source Detail
A22: Total Mil Rate | B22: 13.85 | C22: Freeport Assessor [Fn 5]
A23: RSU Share (FY25 proxy) | B23: 0.716 | C23: FY25 Budget Presentation [Fn 6]
A24: Taxable Valuation | B24: 2613679115 | C24: Budget Handbook [Fn 3]
A25: State Valuation | B25: 2510750000 | C25: Budget Handbook [Fn 3]
A27: DURHAM
A28: SOURCE: Durham FY26 tax rate $33.58/thousand, ~53% assessment ratio [Fn 7]
A29: Durham Assessor, committed 08/12/2025. https://durhammaine.gov/pages/assessing
A30: Note: computed assessment ratio (taxable/state val) = 56.2%, vs. Assessor's stated ~53%.
A31: Valuations from FY27 Budget Handbook [Fn 3].
A32: Item | B32: Value | C32: Source Detail
A33: Total Mil Rate | B33: 33.58 | C33: Durham Assessor [Fn 7]
A34: Taxable Valuation | B34: 389646650 | C34: Budget Handbook [Fn 3]
A35: State Valuation | B35: 692816667 | C35: Budget Handbook [Fn 3]
A37: MAINE EPS FUNDING (FY25-26)
A38: SOURCE: Maine DOE FY25-26 Warrant Article F: Education Subsidy Information (09/09/2025) [Fn 8]
A39: URL: https://www.maine.gov/doe/sites/maine.gov.doe/files/inline-files/School%20Finance%20-%20FY25-26%20Warrant%20Article%20F%20Education%20Subsidy%20Information%20for%20Property%20Tax%20Bill%20-%209.9.2025.pdf
A40: Town | B40: Total EPS Allocation | C40: Local Share | D40: EPS Mill Rate | E40: State Share
A41: Pownal | B41: 2682829 | C41: 2179326.7 | D41: 6.1 | E41: 503502.31
A42: Durham | B42: 9123076.7 | C42: 3655120 | D42: 6.1 | E42: 5467956.7
A43: Freeport | B43: 15033673 | C43: 13799841 | D43: 5.95 | E43: 1233832.6

Sheet I-ECCosts
A1: INPUT: Early Childhood (CDS Transition) Costs
A3: SOURCE: RSU 5 Service Model Options PK3, presented at Dec 18, 2025 Task Force meeting [Fn 19]
A4: URL: https://www.rsu5.org/fs/resource-manager/view/da1426f4-8cc1-4b09-bd89-477da9c623ed
A5: Task Force membership and schedule: https://www.rsu5.org/quick-links/early-childhood-planning-cds [Fn 18]
A6: EC mandate: Portland Press Herald, 10/02/2025 [Fn 17]. Deadline: July 1, 2028 statewide;
A7: RSU 5 committed to Cohort 3 (July 2027) per Superintendent's 02/11/2026 presentation [Fn 10].
A8: NOTE: EC costs are FY28 expenses (begin July 2027). They do NOT appear in the FY27 budget.
A10: Option 1: School-Based with SpEd Classroom (Task Force Recommended)
A11: Position | B11: Unit Cost | C11: Count | D11: Total
A12: ECSE Coordinator (Asst. Director) | B12: 176000 | C12: 1 | D12: 176000
A13: Office Support / Transport Coord. | B13: 105000 | C13: 1 | D13: 105000
A14: SpEd Teacher (282B) | B14: 144000 | C14: 1 | D14: 144000
A15: Ed Techs | B15: 53000 | C15: 3 | D15: 159000
A16: Speech-Language Pathologist | B16: 177000 | C16: 1 | D16: 177000
A17: Social Worker | B17: 177000 | C17: 1 | D17: 177000
A18: Driver Hours | B18: 13000 | C18: 1 | D18: 13000
A19: Contractors (Psych, TOD, TVI, etc.) | B19: 177000 | C19: 1 | D19: 177000
A21: Equipment (van, tech, assessments) | D21: 61644
A23: Estimated State/Federal Offsets
A24: CDS budget transfer: State transfers existing CDS funding per child served [Fn 17].
A25: IDEA Part B: Federal special ed dollars follow children to districts (federal guidelines).
A26: EPS PreK subsidy: Maine DOE Public Pre-K Guidebook (01/21/2025) [Fn 15].
A27: NOTE: These are estimated ranges. Actual amounts depend on enrollment and state allocations.
A28: Offset Source | B28: Low Estimate | C28: High Estimate
A29: CDS budget transfer to districts [Fn 17] | B29: 200000 | C29: 400000
A30: IDEA Part B (federal 3-5 funding) | B30: 100000 | C30: 150000
A31: EPS subsidy for PreK students [Fn 15] | B31: 50000 | C31: 100000

Sheet I-Assumptions
A1: INPUT: Analyst Assumptions & Estimates
A3: These are assumptions used in scenario modeling. They are NOT from official RSU 5 documents.
A4: Each assumption is sourced where possible; otherwise marked as analyst estimate.
A5: Users should adjust these values to test sensitivity of results.
A7: Assumption | B7: Value | C7: Source / Rationale
A8: Cost per FTE (salary + benefits) | B8: 107700 | C8: Derived from budget articles average compensation [Fn 2]
A9: 7-8 target class size | B9: 22 | C9: RSU 5 current middle school practice [Fn 1]
A10: 6th grade target class size | B10: 20 | C10: Upper elementary norm; lower than MS to reflect transition year
